<?xml version="1.0"?>
<robot name="ptu_d46" xmlns:xacro="http://www.ros.org/wiki/xacro">
  <xacro:property name="pan_velocity" value="1.0" />
  <xacro:property name="pan_range" value="2.775" />
  <xacro:property name="tilt_velocity" value="1.0" />
  <xacro:property name="tilt_up_range" value="0.52" />
  <xacro:property name="tilt_down_range" value="0.82" />
  <xacro:property name="joint_effort" value="30" />

  <xacro:macro name="d46_transmission" params="name">
    <transmission name="${name}_trans">
      <type>transmission_interface/SimpleTransmission</type>
      <joint name="${name}">
        <hardwareInterface>PositionJointInterface</hardwareInterface>
      </joint>
      <actuator name="${name}_motor">
        <mechanicalReduction>1</mechanicalReduction>
      </actuator>
    </transmission>
  </xacro:macro>

  <xacro:macro name="ptu_d46" params="name pan_offset:=0.0">
    <link name="${name}_tilt_link">
      <inertial>
        <mass value="0.65" />
        <origin xyz="0 0 0" rpy="0 0 0" />
        <inertia ixx="0.0001" ixy="0" ixz="0" iyy="0.0001" iyz="0" izz="0.0001" />
      </inertial>
      <visual>
        <material name="ptu_body_color">
          <color rgba="0.3 0.3 0.3 1.0" />
        </material>
        <geometry>
          <mesh filename="package://flir_ptu_description/meshes/flir-ptu-tilt-motor.stl"/>
        </geometry>
      </visual>
      <collision>
        <geometry>
          <mesh filename="package://flir_ptu_description/meshes/flir-ptu-tilt-motor-collision.stl"/>
        </geometry>
      </collision>
    </link>
    <gazebo reference="${name}_tilt_link">
        <material>Gazebo/DarkGrey</material>
    </gazebo>

    <link name="${name}_pan_link">
      <inertial>
        <mass value="0.65" />
        <origin xyz="0 0 0" rpy="0 0 0" />
        <inertia ixx="0.0001" ixy="0" ixz="0" iyy="0.0001" iyz="0" izz="0.0001" />
      </inertial>
      <visual>
        <material name="ptu_body_color">
          <color rgba="0.3 0.3 0.3 1.0" />
        </material>
        <geometry>
          <mesh filename="package://flir_ptu_description/meshes/flir-ptu-pan-motor.stl"/>
        </geometry>
      </visual>
      <collision>
        <geometry>
          <mesh filename="package://flir_ptu_description/meshes/flir-ptu-pan-motor-collision.stl"/>
        </geometry>
      </collision>
    </link>
    <gazebo reference="${name}_pan_link">
        <material>Gazebo/DarkGrey</material>
    </gazebo>

    <link name="${name}_base_link">
       <inertial>
            <mass value="2e-06"/>
            <inertia ixx="1.1e-09" ixy="0" ixz="0" iyy="1.1e-09" iyz="0" izz="1.1e-09"/>
        </inertial>
    </link>
    <link name="${name}_tilted_link">
      <visual>
        <material name="ptu_body_color">
          <color rgba="0.3 0.3 0.3 1.0" />
        </material>
        <geometry>
          <mesh filename="package://flir_ptu_description/meshes/flir-ptu-camera-mount.stl"/>
        </geometry>
      </visual>
      <collision>
        <geometry>
          <mesh filename="package://flir_ptu_description/meshes/flir-ptu-camera-mount.stl"/>
        </geometry>
      </collision>
    </link>
    <link name="${name}_mount_link">
        <inertial>
            <mass value="2e-06"/>
            <inertia ixx="1.1e-09" ixy="0" ixz="0" iyy="1.1e-09" iyz="0" izz="1.1e-09"/>
        </inertial>
    </link>

    <joint name="${name}_base" type="fixed">
      <parent link="${name}_base_link"/>
      <child link="${name}_pan_link"/>
      <origin xyz="0 0 0"/>
    </joint>

    <!-- The pan joint -->
    <joint name="${name}_pan" type="revolute">
      <parent link="${name}_pan_link" />
      <origin xyz="0 -0.00955 0.046774" rpy="-1.5708 0 ${pan_offset}" />
      <child link="${name}_tilt_link" />
      <axis xyz="0 -1 0" rpy="3.14159 0 0" />
      <limit lower="${-pan_range}" upper="${pan_range}"
             effort="${joint_effort}" velocity="${pan_velocity}" />
    </joint>

    <xacro:d46_transmission name="${name}_pan" />

    <!-- The tilt joint -->
    <joint name="${name}_tilt" type="revolute">
      <parent link="${name}_tilt_link" />
      <origin xyz="0 -0.043713 0" rpy="-1.5708 0 0" />
      <child link="${name}_tilted_link" />
      <axis xyz="0 1 0" />
      <limit lower="${-tilt_down_range}" upper="${tilt_up_range}"
             effort="${joint_effort}" velocity="${tilt_velocity}" />
    </joint>

    <xacro:d46_transmission name="${name}_tilt" />

    <!-- Fixed joint to provide a convenient attachment point for accessories. -->
    <joint name="${name}_mount" type="fixed">
      <parent link="${name}_tilted_link"/>
      <child link="${name}_mount_link"/>
      <origin xyz="0 0 -0.039116" rpy="3.1416 0 0" />
    </joint>

  </xacro:macro>
</robot>
